{
    "containers": {
        "cna": {
            "affected": [
                {
                    "product": "n/a",
                    "vendor": "n/a",
                    "versions": [
                        {
                            "status": "affected",
                            "version": "n/a"
                        }
                    ]
                }
            ],
            "datePublic": "2010-09-09T00:00:00",
            "descriptions": [
                {
                    "lang": "en",
                    "value": "Race condition in ZEO/StorageServer.py in Zope Object Database (ZODB) before 3.10.0 allows remote attackers to cause a denial of service (daemon outage) by establishing and then immediately closing a TCP connection, leading to the accept function having an unexpected return value of None, an unexpected value of None for the address, or an ECONNABORTED, EAGAIN, or EWOULDBLOCK error, a related issue to CVE-2010-3492."
                }
            ],
            "problemTypes": [
                {
                    "descriptions": [
                        {
                            "description": "n/a",
                            "lang": "en",
                            "type": "text"
                        }
                    ]
                }
            ],
            "providerMetadata": {
                "dateUpdated": "2011-01-22T10:00:00",
                "orgId": "8254265b-2729-46b6-b9e3-3dfca2d5bfca",
                "shortName": "mitre"
            },
            "references": [
                {
                    "name": "[oss-security] 20100910 Re: CVE Request -- Python -- accept() implementation in async core is broken => more subcases",
                    "tags": [
                        "mailing-list",
                        "x_refsource_MLIST"
                    ],
                    "url": "http://www.openwall.com/lists/oss-security/2010/09/11/2"
                },
                {
                    "tags": [
                        "x_refsource_CONFIRM"
                    ],
                    "url": "https://bugs.launchpad.net/zodb/+bug/135108"
                },
                {
                    "tags": [
                        "x_refsource_CONFIRM"
                    ],
                    "url": "http://pypi.python.org/pypi/ZODB3/3.10.0#id1"
                },
                {
                    "name": "[oss-security] 20100924 Re: CVE Request -- Python -- accept() implementation in async core is broken => more subcases",
                    "tags": [
                        "mailing-list",
                        "x_refsource_MLIST"
                    ],
                    "url": "http://www.openwall.com/lists/oss-security/2010/09/24/3"
                },
                {
                    "name": "[oss-security] 20100922 Re: CVE Request -- Python -- accept() implementation in async core is broken => more subcases",
                    "tags": [
                        "mailing-list",
                        "x_refsource_MLIST"
                    ],
                    "url": "http://www.openwall.com/lists/oss-security/2010/09/22/3"
                },
                {
                    "tags": [
                        "x_refsource_MISC"
                    ],
                    "url": "http://bugs.python.org/issue6706"
                },
                {
                    "name": "[oss-security] 20100909 CVE Request -- Python -- accept() implementation in async core is broken => more subcases",
                    "tags": [
                        "mailing-list",
                        "x_refsource_MLIST"
                    ],
                    "url": "http://www.openwall.com/lists/oss-security/2010/09/09/6"
                },
                {
                    "name": "SUSE-SR:2010:024",
                    "tags": [
                        "vendor-advisory",
                        "x_refsource_SUSE"
                    ],
                    "url": "http://lists.opensuse.org/opensuse-security-announce/2010-12/msg00006.html"
                },
                {
                    "name": "41755",
                    "tags": [
                        "third-party-advisory",
                        "x_refsource_SECUNIA"
                    ],
                    "url": "http://secunia.com/advisories/41755"
                }
            ],
            "x_legacyV4Record": {
                "CVE_data_meta": {
                    "ASSIGNER": "cve@mitre.org",
                    "ID": "CVE-2010-3495",
                    "STATE": "PUBLIC"
                },
                "affects": {
                    "vendor": {
                        "vendor_data": [
                            {
                                "product": {
                                    "product_data": [
                                        {
                                            "product_name": "n/a",
                                            "version": {
                                                "version_data": [
                                                    {
                                                        "version_value": "n/a"
                                                    }
                                                ]
                                            }
                                        }
                                    ]
                                },
                                "vendor_name": "n/a"
                            }
                        ]
                    }
                },
                "data_format": "MITRE",
                "data_type": "CVE",
                "data_version": "4.0",
                "description": {
                    "description_data": [
                        {
                            "lang": "eng",
                            "value": "Race condition in ZEO/StorageServer.py in Zope Object Database (ZODB) before 3.10.0 allows remote attackers to cause a denial of service (daemon outage) by establishing and then immediately closing a TCP connection, leading to the accept function having an unexpected return value of None, an unexpected value of None for the address, or an ECONNABORTED, EAGAIN, or EWOULDBLOCK error, a related issue to CVE-2010-3492."
                        }
                    ]
                },
                "problemtype": {
                    "problemtype_data": [
                        {
                            "description": [
                                {
                                    "lang": "eng",
                                    "value": "n/a"
                                }
                            ]
                        }
                    ]
                },
                "references": {
                    "reference_data": [
                        {
                            "name": "[oss-security] 20100910 Re: CVE Request -- Python -- accept() implementation in async core is broken => more subcases",
                            "refsource": "MLIST",
                            "url": "http://www.openwall.com/lists/oss-security/2010/09/11/2"
                        },
                        {
                            "name": "https://bugs.launchpad.net/zodb/+bug/135108",
                            "refsource": "CONFIRM",
                            "url": "https://bugs.launchpad.net/zodb/+bug/135108"
                        },
                        {
                            "name": "http://pypi.python.org/pypi/ZODB3/3.10.0#id1",
                            "refsource": "CONFIRM",
                            "url": "http://pypi.python.org/pypi/ZODB3/3.10.0#id1"
                        },
                        {
                            "name": "[oss-security] 20100924 Re: CVE Request -- Python -- accept() implementation in async core is broken => more subcases",
                            "refsource": "MLIST",
                            "url": "http://www.openwall.com/lists/oss-security/2010/09/24/3"
                        },
                        {
                            "name": "[oss-security] 20100922 Re: CVE Request -- Python -- accept() implementation in async core is broken => more subcases",
                            "refsource": "MLIST",
                            "url": "http://www.openwall.com/lists/oss-security/2010/09/22/3"
                        },
                        {
                            "name": "http://bugs.python.org/issue6706",
                            "refsource": "MISC",
                            "url": "http://bugs.python.org/issue6706"
                        },
                        {
                            "name": "[oss-security] 20100909 CVE Request -- Python -- accept() implementation in async core is broken => more subcases",
                            "refsource": "MLIST",
                            "url": "http://www.openwall.com/lists/oss-security/2010/09/09/6"
                        },
                        {
                            "name": "SUSE-SR:2010:024",
                            "refsource": "SUSE",
                            "url": "http://lists.opensuse.org/opensuse-security-announce/2010-12/msg00006.html"
                        },
                        {
                            "name": "41755",
                            "refsource": "SECUNIA",
                            "url": "http://secunia.com/advisories/41755"
                        }
                    ]
                }
            }
        },
        "adp": [
            {
                "providerMetadata": {
                    "orgId": "96f1cf3c-f80a-4e0f-a063-99a91e3f1325",
                    "shortName": "secretariat-reference",
                    "dateUpdated": "2024-06-29T17:09:02.765Z"
                },
                "references": [
                    {
                        "name": "[oss-security] 20100910 Re: CVE Request -- Python -- accept() implementation in async core is broken => more subcases",
                        "tags": [
                            "mailing-list",
                            "x_refsource_MLIST",
                            "x_cve_prog_secretariat_snapshot"
                        ],
                        "url": "http://www.openwall.com/lists/oss-security/2010/09/11/2/DEMO_2024_06_19"
                    },
                    {
                        "tags": [
                            "x_refsource_CONFIRM",
                            "x_cve_prog_secretariat_snapshot"
                        ],
                        "url": "https://bugs.launchpad.net/zodb/+bug/135108/DEMO_2024_06_19"
                    },
                    {
                        "tags": [
                            "x_refsource_CONFIRM",
                            "x_cve_prog_secretariat_snapshot"
                        ],
                        "url": "http://pypi.python.org/pypi/ZODB3/3.10.0#id1/DEMO_2024_06_19"
                    },
                    {
                        "name": "[oss-security] 20100924 Re: CVE Request -- Python -- accept() implementation in async core is broken => more subcases",
                        "tags": [
                            "mailing-list",
                            "x_refsource_MLIST",
                            "x_cve_prog_secretariat_snapshot"
                        ],
                        "url": "http://www.openwall.com/lists/oss-security/2010/09/24/3/DEMO_2024_06_19"
                    },
                    {
                        "name": "[oss-security] 20100922 Re: CVE Request -- Python -- accept() implementation in async core is broken => more subcases",
                        "tags": [
                            "mailing-list",
                            "x_refsource_MLIST",
                            "x_cve_prog_secretariat_snapshot"
                        ],
                        "url": "http://www.openwall.com/lists/oss-security/2010/09/22/3/DEMO_2024_06_19"
                    },
                    {
                        "tags": [
                            "x_refsource_MISC",
                            "x_cve_prog_secretariat_snapshot"
                        ],
                        "url": "http://bugs.python.org/issue6706/DEMO_2024_06_19"
                    },
                    {
                        "name": "[oss-security] 20100909 CVE Request -- Python -- accept() implementation in async core is broken => more subcases",
                        "tags": [
                            "mailing-list",
                            "x_refsource_MLIST",
                            "x_cve_prog_secretariat_snapshot"
                        ],
                        "url": "http://www.openwall.com/lists/oss-security/2010/09/09/6/DEMO_2024_06_19"
                    },
                    {
                        "name": "SUSE-SR:2010:024",
                        "tags": [
                            "vendor-advisory",
                            "x_refsource_SUSE",
                            "x_cve_prog_secretariat_snapshot"
                        ],
                        "url": "http://lists.opensuse.org/opensuse-security-announce/2010-12/msg00006.html/DEMO_2024_06_19"
                    },
                    {
                        "name": "41755",
                        "tags": [
                            "third-party-advisory",
                            "x_refsource_SECUNIA",
                            "x_cve_prog_secretariat_snapshot"
                        ],
                        "url": "http://secunia.com/advisories/41755/DEMO_2024_06_19"
                    },
                    {
                        "name": "[oss-security] 20100910 Re: CVE Request -- Python -- accept() implementation in async core is broken => more subcases",
                        "tags": [
                            "mailing-list",
                            "x_refsource_MLIST",
                            "x_cve_prog_secretariat_snapshot",
                            "x_cve_prog_secretariat_snapshot@2024-06-28T20:08:51.933Z"
                        ],
                        "url": "http://www.openwall.com/lists/oss-security/2010/09/11/2/adp-test-6-28"
                    },
                    {
                        "tags": [
                            "x_refsource_CONFIRM",
                            "x_cve_prog_secretariat_snapshot",
                            "x_cve_prog_secretariat_snapshot@2024-06-28T20:08:51.933Z"
                        ],
                        "url": "https://bugs.launchpad.net/zodb/+bug/135108/adp-test-6-28"
                    },
                    {
                        "tags": [
                            "x_refsource_CONFIRM",
                            "x_cve_prog_secretariat_snapshot",
                            "x_cve_prog_secretariat_snapshot@2024-06-28T20:08:51.933Z"
                        ],
                        "url": "http://pypi.python.org/pypi/ZODB3/3.10.0#id1/adp-test-6-28"
                    },
                    {
                        "name": "[oss-security] 20100924 Re: CVE Request -- Python -- accept() implementation in async core is broken => more subcases",
                        "tags": [
                            "mailing-list",
                            "x_refsource_MLIST",
                            "x_cve_prog_secretariat_snapshot",
                            "x_cve_prog_secretariat_snapshot@2024-06-28T20:08:51.933Z"
                        ],
                        "url": "http://www.openwall.com/lists/oss-security/2010/09/24/3/adp-test-6-28"
                    },
                    {
                        "name": "[oss-security] 20100922 Re: CVE Request -- Python -- accept() implementation in async core is broken => more subcases",
                        "tags": [
                            "mailing-list",
                            "x_refsource_MLIST",
                            "x_cve_prog_secretariat_snapshot",
                            "x_cve_prog_secretariat_snapshot@2024-06-28T20:08:51.933Z"
                        ],
                        "url": "http://www.openwall.com/lists/oss-security/2010/09/22/3/adp-test-6-28"
                    },
                    {
                        "tags": [
                            "x_refsource_MISC",
                            "x_cve_prog_secretariat_snapshot",
                            "x_cve_prog_secretariat_snapshot@2024-06-28T20:08:51.933Z"
                        ],
                        "url": "http://bugs.python.org/issue6706/adp-test-6-28"
                    },
                    {
                        "name": "[oss-security] 20100909 CVE Request -- Python -- accept() implementation in async core is broken => more subcases",
                        "tags": [
                            "mailing-list",
                            "x_refsource_MLIST",
                            "x_cve_prog_secretariat_snapshot",
                            "x_cve_prog_secretariat_snapshot@2024-06-28T20:08:51.933Z"
                        ],
                        "url": "http://www.openwall.com/lists/oss-security/2010/09/09/6/adp-test-6-28"
                    },
                    {
                        "name": "SUSE-SR:2010:024",
                        "tags": [
                            "vendor-advisory",
                            "x_refsource_SUSE",
                            "x_cve_prog_secretariat_snapshot",
                            "x_cve_prog_secretariat_snapshot@2024-06-28T20:08:51.933Z"
                        ],
                        "url": "http://lists.opensuse.org/opensuse-security-announce/2010-12/msg00006.html/adp-test-6-28"
                    },
                    {
                        "name": "41755",
                        "tags": [
                            "third-party-advisory",
                            "x_refsource_SECUNIA",
                            "x_cve_prog_secretariat_snapshot",
                            "x_cve_prog_secretariat_snapshot@2024-06-28T20:08:51.933Z"
                        ],
                        "url": "http://secunia.com/advisories/41755/adp-test-6-28"
                    }
                ]
            }
        ]
    },
    "cveMetadata": {
        "assignerOrgId": "8254265b-2729-46b6-b9e3-3dfca2d5bfca",
        "assignerShortName": "mitre",
        "cveId": "CVE-2010-3495",
        "datePublished": "2010-10-19T19:00:00",
        "dateReserved": "2010-09-24T00:00:00",
        "dateUpdated": "2024-06-29T17:09:02.765Z",
        "state": "PUBLISHED"
    },
    "dataType": "CVE_RECORD",
    "dataVersion": "5.1"
}