{
    "containers": {
        "cna": {
            "affected": [
                {
                    "product": "n/a",
                    "vendor": "n/a",
                    "versions": [
                        {
                            "status": "affected",
                            "version": "n/a"
                        }
                    ]
                }
            ],
            "descriptions": [
                {
                    "lang": "en",
                    "value": "Race condition in the FTPHandler class in ftpserver.py in pyftpdlib before 0.5.2 allows remote attackers to cause a denial of service (daemon outage) by establishing and then immediately closing a TCP connection, leading to the accept function having an unexpected value of None for the address, or an ECONNABORTED, EAGAIN, or EWOULDBLOCK error, a related issue to CVE-2010-3492."
                }
            ],
            "problemTypes": [
                {
                    "descriptions": [
                        {
                            "description": "n/a",
                            "lang": "en",
                            "type": "text"
                        }
                    ]
                }
            ],
            "providerMetadata": {
                "dateUpdated": "2022-10-03T16:20:56",
                "orgId": "8254265b-2729-46b6-b9e3-3dfca2d5bfca",
                "shortName": "mitre"
            },
            "references": [
                {
                    "name": "[oss-security] 20100910 Re: CVE Request -- Python -- accept() implementation in async core is broken => more subcases",
                    "tags": [
                        "mailing-list",
                        "x_refsource_MLIST"
                    ],
                    "url": "http://www.openwall.com/lists/oss-security/2010/09/11/2"
                },
                {
                    "tags": [
                        "x_refsource_CONFIRM"
                    ],
                    "url": "http://code.google.com/p/pyftpdlib/source/detail?r=556"
                },
                {
                    "tags": [
                        "x_refsource_CONFIRM"
                    ],
                    "url": "http://code.google.com/p/pyftpdlib/source/browse/trunk/HISTORY"
                },
                {
                    "tags": [
                        "x_refsource_MISC"
                    ],
                    "url": "https://bugs.launchpad.net/zodb/+bug/135108"
                },
                {
                    "tags": [
                        "x_refsource_CONFIRM"
                    ],
                    "url": "http://code.google.com/p/pyftpdlib/source/diff?spec=svn556&r=556&format=side&path=/trunk/pyftpdlib/ftpserver.py"
                },
                {
                    "tags": [
                        "x_refsource_CONFIRM"
                    ],
                    "url": "http://code.google.com/p/pyftpdlib/issues/detail?id=105"
                },
                {
                    "name": "[oss-security] 20100924 Re: CVE Request -- Python -- accept() implementation in async core is broken => more subcases",
                    "tags": [
                        "mailing-list",
                        "x_refsource_MLIST"
                    ],
                    "url": "http://www.openwall.com/lists/oss-security/2010/09/24/3"
                },
                {
                    "name": "[oss-security] 20100922 Re: CVE Request -- Python -- accept() implementation in async core is broken => more subcases",
                    "tags": [
                        "mailing-list",
                        "x_refsource_MLIST"
                    ],
                    "url": "http://www.openwall.com/lists/oss-security/2010/09/22/3"
                },
                {
                    "tags": [
                        "x_refsource_CONFIRM"
                    ],
                    "url": "http://code.google.com/p/pyftpdlib/issues/detail?id=104"
                },
                {
                    "tags": [
                        "x_refsource_MISC"
                    ],
                    "url": "http://bugs.python.org/issue6706"
                },
                {
                    "name": "[oss-security] 20100909 CVE Request -- Python -- accept() implementation in async core is broken => more subcases",
                    "tags": [
                        "mailing-list",
                        "x_refsource_MLIST"
                    ],
                    "url": "http://www.openwall.com/lists/oss-security/2010/09/09/6"
                }
            ],
            "x_legacyV4Record": {
                "CVE_data_meta": {
                    "ASSIGNER": "cve@mitre.org",
                    "ID": "CVE-2010-3494",
                    "STATE": "PUBLIC"
                },
                "affects": {
                    "vendor": {
                        "vendor_data": [
                            {
                                "product": {
                                    "product_data": [
                                        {
                                            "product_name": "n/a",
                                            "version": {
                                                "version_data": [
                                                    {
                                                        "version_value": "n/a"
                                                    }
                                                ]
                                            }
                                        }
                                    ]
                                },
                                "vendor_name": "n/a"
                            }
                        ]
                    }
                },
                "data_format": "MITRE",
                "data_type": "CVE",
                "data_version": "4.0",
                "description": {
                    "description_data": [
                        {
                            "lang": "eng",
                            "value": "Race condition in the FTPHandler class in ftpserver.py in pyftpdlib before 0.5.2 allows remote attackers to cause a denial of service (daemon outage) by establishing and then immediately closing a TCP connection, leading to the accept function having an unexpected value of None for the address, or an ECONNABORTED, EAGAIN, or EWOULDBLOCK error, a related issue to CVE-2010-3492."
                        }
                    ]
                },
                "problemtype": {
                    "problemtype_data": [
                        {
                            "description": [
                                {
                                    "lang": "eng",
                                    "value": "n/a"
                                }
                            ]
                        }
                    ]
                },
                "references": {
                    "reference_data": [
                        {
                            "name": "[oss-security] 20100910 Re: CVE Request -- Python -- accept() implementation in async core is broken => more subcases",
                            "refsource": "MLIST",
                            "url": "http://www.openwall.com/lists/oss-security/2010/09/11/2"
                        },
                        {
                            "name": "http://code.google.com/p/pyftpdlib/source/detail?r=556",
                            "refsource": "CONFIRM",
                            "url": "http://code.google.com/p/pyftpdlib/source/detail?r=556"
                        },
                        {
                            "name": "http://code.google.com/p/pyftpdlib/source/browse/trunk/HISTORY",
                            "refsource": "CONFIRM",
                            "url": "http://code.google.com/p/pyftpdlib/source/browse/trunk/HISTORY"
                        },
                        {
                            "name": "https://bugs.launchpad.net/zodb/+bug/135108",
                            "refsource": "MISC",
                            "url": "https://bugs.launchpad.net/zodb/+bug/135108"
                        },
                        {
                            "name": "http://code.google.com/p/pyftpdlib/source/diff?spec=svn556&r=556&format=side&path=/trunk/pyftpdlib/ftpserver.py",
                            "refsource": "CONFIRM",
                            "url": "http://code.google.com/p/pyftpdlib/source/diff?spec=svn556&r=556&format=side&path=/trunk/pyftpdlib/ftpserver.py"
                        },
                        {
                            "name": "http://code.google.com/p/pyftpdlib/issues/detail?id=105",
                            "refsource": "CONFIRM",
                            "url": "http://code.google.com/p/pyftpdlib/issues/detail?id=105"
                        },
                        {
                            "name": "[oss-security] 20100924 Re: CVE Request -- Python -- accept() implementation in async core is broken => more subcases",
                            "refsource": "MLIST",
                            "url": "http://www.openwall.com/lists/oss-security/2010/09/24/3"
                        },
                        {
                            "name": "[oss-security] 20100922 Re: CVE Request -- Python -- accept() implementation in async core is broken => more subcases",
                            "refsource": "MLIST",
                            "url": "http://www.openwall.com/lists/oss-security/2010/09/22/3"
                        },
                        {
                            "name": "http://code.google.com/p/pyftpdlib/issues/detail?id=104",
                            "refsource": "CONFIRM",
                            "url": "http://code.google.com/p/pyftpdlib/issues/detail?id=104"
                        },
                        {
                            "name": "http://bugs.python.org/issue6706",
                            "refsource": "MISC",
                            "url": "http://bugs.python.org/issue6706"
                        },
                        {
                            "name": "[oss-security] 20100909 CVE Request -- Python -- accept() implementation in async core is broken => more subcases",
                            "refsource": "MLIST",
                            "url": "http://www.openwall.com/lists/oss-security/2010/09/09/6"
                        }
                    ]
                }
            }
        },
        "adp": [
            {
                "providerMetadata": {
                    "orgId": "96f1cf3c-f80a-4e0f-a063-99a91e3f1325",
                    "shortName": "secretariat-reference",
                    "dateUpdated": "2024-06-29T17:09:02.757Z"
                },
                "references": [
                    {
                        "name": "[oss-security] 20100910 Re: CVE Request -- Python -- accept() implementation in async core is broken => more subcases",
                        "tags": [
                            "mailing-list",
                            "x_refsource_MLIST",
                            "x_cve_prog_secretariat_snapshot"
                        ],
                        "url": "http://www.openwall.com/lists/oss-security/2010/09/11/2/DEMO_2024_06_19"
                    },
                    {
                        "tags": [
                            "x_refsource_CONFIRM",
                            "x_cve_prog_secretariat_snapshot"
                        ],
                        "url": "http://code.google.com/p/pyftpdlib/source/detail?r=556/DEMO_2024_06_19"
                    },
                    {
                        "tags": [
                            "x_refsource_CONFIRM",
                            "x_cve_prog_secretariat_snapshot"
                        ],
                        "url": "http://code.google.com/p/pyftpdlib/source/browse/trunk/HISTORY/DEMO_2024_06_19"
                    },
                    {
                        "tags": [
                            "x_refsource_MISC",
                            "x_cve_prog_secretariat_snapshot"
                        ],
                        "url": "https://bugs.launchpad.net/zodb/+bug/135108/DEMO_2024_06_19"
                    },
                    {
                        "tags": [
                            "x_refsource_CONFIRM",
                            "x_cve_prog_secretariat_snapshot"
                        ],
                        "url": "http://code.google.com/p/pyftpdlib/source/diff?spec=svn556&r=556&format=side&path=/trunk/pyftpdlib/ftpserver.py/DEMO_2024_06_19"
                    },
                    {
                        "tags": [
                            "x_refsource_CONFIRM",
                            "x_cve_prog_secretariat_snapshot"
                        ],
                        "url": "http://code.google.com/p/pyftpdlib/issues/detail?id=105/DEMO_2024_06_19"
                    },
                    {
                        "name": "[oss-security] 20100924 Re: CVE Request -- Python -- accept() implementation in async core is broken => more subcases",
                        "tags": [
                            "mailing-list",
                            "x_refsource_MLIST",
                            "x_cve_prog_secretariat_snapshot"
                        ],
                        "url": "http://www.openwall.com/lists/oss-security/2010/09/24/3/DEMO_2024_06_19"
                    },
                    {
                        "name": "[oss-security] 20100922 Re: CVE Request -- Python -- accept() implementation in async core is broken => more subcases",
                        "tags": [
                            "mailing-list",
                            "x_refsource_MLIST",
                            "x_cve_prog_secretariat_snapshot"
                        ],
                        "url": "http://www.openwall.com/lists/oss-security/2010/09/22/3/DEMO_2024_06_19"
                    },
                    {
                        "tags": [
                            "x_refsource_CONFIRM",
                            "x_cve_prog_secretariat_snapshot"
                        ],
                        "url": "http://code.google.com/p/pyftpdlib/issues/detail?id=104/DEMO_2024_06_19"
                    },
                    {
                        "tags": [
                            "x_refsource_MISC",
                            "x_cve_prog_secretariat_snapshot"
                        ],
                        "url": "http://bugs.python.org/issue6706/DEMO_2024_06_19"
                    },
                    {
                        "name": "[oss-security] 20100909 CVE Request -- Python -- accept() implementation in async core is broken => more subcases",
                        "tags": [
                            "mailing-list",
                            "x_refsource_MLIST",
                            "x_cve_prog_secretariat_snapshot"
                        ],
                        "url": "http://www.openwall.com/lists/oss-security/2010/09/09/6/DEMO_2024_06_19"
                    },
                    {
                        "name": "[oss-security] 20100910 Re: CVE Request -- Python -- accept() implementation in async core is broken => more subcases",
                        "tags": [
                            "mailing-list",
                            "x_refsource_MLIST",
                            "x_cve_prog_secretariat_snapshot",
                            "x_cve_prog_secretariat_snapshot@2024-06-28T20:08:51.933Z"
                        ],
                        "url": "http://www.openwall.com/lists/oss-security/2010/09/11/2/adp-test-6-28"
                    },
                    {
                        "tags": [
                            "x_refsource_CONFIRM",
                            "x_cve_prog_secretariat_snapshot",
                            "x_cve_prog_secretariat_snapshot@2024-06-28T20:08:51.933Z"
                        ],
                        "url": "http://code.google.com/p/pyftpdlib/source/detail?r=556/adp-test-6-28"
                    },
                    {
                        "tags": [
                            "x_refsource_CONFIRM",
                            "x_cve_prog_secretariat_snapshot",
                            "x_cve_prog_secretariat_snapshot@2024-06-28T20:08:51.933Z"
                        ],
                        "url": "http://code.google.com/p/pyftpdlib/source/browse/trunk/HISTORY/adp-test-6-28"
                    },
                    {
                        "tags": [
                            "x_refsource_MISC",
                            "x_cve_prog_secretariat_snapshot",
                            "x_cve_prog_secretariat_snapshot@2024-06-28T20:08:51.933Z"
                        ],
                        "url": "https://bugs.launchpad.net/zodb/+bug/135108/adp-test-6-28"
                    },
                    {
                        "tags": [
                            "x_refsource_CONFIRM",
                            "x_cve_prog_secretariat_snapshot",
                            "x_cve_prog_secretariat_snapshot@2024-06-28T20:08:51.933Z"
                        ],
                        "url": "http://code.google.com/p/pyftpdlib/source/diff?spec=svn556&r=556&format=side&path=/trunk/pyftpdlib/ftpserver.py/adp-test-6-28"
                    },
                    {
                        "tags": [
                            "x_refsource_CONFIRM",
                            "x_cve_prog_secretariat_snapshot",
                            "x_cve_prog_secretariat_snapshot@2024-06-28T20:08:51.933Z"
                        ],
                        "url": "http://code.google.com/p/pyftpdlib/issues/detail?id=105/adp-test-6-28"
                    },
                    {
                        "name": "[oss-security] 20100924 Re: CVE Request -- Python -- accept() implementation in async core is broken => more subcases",
                        "tags": [
                            "mailing-list",
                            "x_refsource_MLIST",
                            "x_cve_prog_secretariat_snapshot",
                            "x_cve_prog_secretariat_snapshot@2024-06-28T20:08:51.933Z"
                        ],
                        "url": "http://www.openwall.com/lists/oss-security/2010/09/24/3/adp-test-6-28"
                    },
                    {
                        "name": "[oss-security] 20100922 Re: CVE Request -- Python -- accept() implementation in async core is broken => more subcases",
                        "tags": [
                            "mailing-list",
                            "x_refsource_MLIST",
                            "x_cve_prog_secretariat_snapshot",
                            "x_cve_prog_secretariat_snapshot@2024-06-28T20:08:51.933Z"
                        ],
                        "url": "http://www.openwall.com/lists/oss-security/2010/09/22/3/adp-test-6-28"
                    },
                    {
                        "tags": [
                            "x_refsource_CONFIRM",
                            "x_cve_prog_secretariat_snapshot",
                            "x_cve_prog_secretariat_snapshot@2024-06-28T20:08:51.933Z"
                        ],
                        "url": "http://code.google.com/p/pyftpdlib/issues/detail?id=104/adp-test-6-28"
                    },
                    {
                        "tags": [
                            "x_refsource_MISC",
                            "x_cve_prog_secretariat_snapshot",
                            "x_cve_prog_secretariat_snapshot@2024-06-28T20:08:51.933Z"
                        ],
                        "url": "http://bugs.python.org/issue6706/adp-test-6-28"
                    },
                    {
                        "name": "[oss-security] 20100909 CVE Request -- Python -- accept() implementation in async core is broken => more subcases",
                        "tags": [
                            "mailing-list",
                            "x_refsource_MLIST",
                            "x_cve_prog_secretariat_snapshot",
                            "x_cve_prog_secretariat_snapshot@2024-06-28T20:08:51.933Z"
                        ],
                        "url": "http://www.openwall.com/lists/oss-security/2010/09/09/6/adp-test-6-28"
                    }
                ]
            }
        ]
    },
    "cveMetadata": {
        "assignerOrgId": "8254265b-2729-46b6-b9e3-3dfca2d5bfca",
        "assignerShortName": "mitre",
        "cveId": "CVE-2010-3494",
        "datePublished": "2022-10-03T16:20:56",
        "dateReserved": "2022-10-03T00:00:00",
        "dateUpdated": "2024-06-29T17:09:02.757Z",
        "state": "PUBLISHED"
    },
    "dataType": "CVE_RECORD",
    "dataVersion": "5.1"
}